Traceback (most recent call last):
  File "/gpfs/spack/opt/linux-rocky8-icelake/gcc-8.5.0/anaconda3-2022.10-4dp3trddxrrzcg6rozuot7ckgh3zjche/lib/python3.9/site-packages/pandas/core/indexes/base.py", line 3629, in get_loc
    return self._engine.get_loc(casted_key)
  File "pandas/_libs/index.pyx", line 136, in pandas._libs.index.IndexEngine.get_loc
  File "pandas/_libs/index.pyx", line 163, in pandas._libs.index.IndexEngine.get_loc
  File "pandas/_libs/hashtable_class_helper.pxi", line 5198, in pandas._libs.hashtable.PyObjectHashTable.get_item
  File "pandas/_libs/hashtable_class_helper.pxi", line 5206, in pandas._libs.hashtable.PyObjectHashTable.get_item
KeyError: 'i-Evalue'

The above exception was the direct cause of the following exception:

Traceback (most recent call last):
  File "/gpfs/work/bio/yueqingxing22/igem/HMM/functional_annotator.py", line 162, in <module>
    args.func(args)
  File "/gpfs/work/bio/yueqingxing22/igem/HMM/functional_annotator.py", line 146, in <lambda>
    p2.set_defaults(func=lambda args: annotate_unknown(
  File "/gpfs/work/bio/yueqingxing22/igem/HMM/functional_annotator.py", line 88, in annotate_unknown
    df_filt = filter_hits(df, iE=iE, bits=bits, qcov=qcov)
  File "/gpfs/work/bio/yueqingxing22/igem/HMM/functional_annotator.py", line 39, in filter_hits
    df["i-Evalue"] = pd.to_numeric(df["i-Evalue"], errors="coerce")
  File "/gpfs/spack/opt/linux-rocky8-icelake/gcc-8.5.0/anaconda3-2022.10-4dp3trddxrrzcg6rozuot7ckgh3zjche/lib/python3.9/site-packages/pandas/core/frame.py", line 3505, in __getitem__
    indexer = self.columns.get_loc(key)
  File "/gpfs/spack/opt/linux-rocky8-icelake/gcc-8.5.0/anaconda3-2022.10-4dp3trddxrrzcg6rozuot7ckgh3zjche/lib/python3.9/site-packages/pandas/core/indexes/base.py", line 3631, in get_loc
    raise KeyError(key) from err
KeyError: 'i-Evalue'
